<robot
  name="agv">
  <link
    name="base_link">
    <inertial>
      <origin
        xyz="-1.2283E-08 -3.2287E-08 -0.26752"
        rpy="0 0 0" />
      <mass
        value="396" />
      <inertia
        ixx="47.751"
        ixy="-2.6583"
        ixz="1.0069E-06"
        iyy="27.544"
        iyz="2.649E-06"
        izz="54.619" />
    </inertial>
    <visual>
      <origin
        xyz="0 0 0"
        rpy="0 0 0" />
      <geometry>
        <mesh
          filename="package://agv/meshes/base_link.STL" />
      </geometry>
      <material
        name="">
        <color
          rgba="1 1 1 1" />
      </material>
    </visual>
    <collision>
      <origin
        xyz="0 0 0"
        rpy="0 0 0" />
      <geometry>
        <mesh
          filename="package://agv/meshes/base_link.STL" />
      </geometry>
    </collision>
  </link>
  <link
    name="left_back">
    <inertial>
      <origin
        xyz="4.2234E-08 0.00063256 0.005438"
        rpy="0 0 0" />
      <mass
        value="2.9202" />
      <inertia
        ixx="0.015924"
        ixy="1.5152E-08"
        ixz="-8.5411E-09"
        iyy="0.016069"
        iyz="0.0012521"
        izz="0.026687" />
    </inertial>
    <visual>
      <origin
        xyz="0 0 0"
        rpy="0 0 0" />
      <geometry>
        <mesh
          filename="package://agv/meshes/left_back.STL" />
      </geometry>
      <material
        name="">
        <color
          rgba="1 1 1 1" />
      </material>
    </visual>
    <collision>
      <origin
        xyz="0 0 0"
        rpy="0 0 0" />
      <geometry>
        <mesh
          filename="package://agv/meshes/left_back.STL" />
      </geometry>
    </collision>
  </link>
  <joint
    name="left_back_joint"
    type="continuous">
    <origin
      xyz="0.30735 0.327 -0.527"
      rpy="-3.1378 -1.5708 0.11203" />
    <parent
      link="base_link" />
    <child
      link="left_back" />
    <axis
      xyz="0 0.11555 0.9933" />
    <limit
      lower="2"
      upper="10"
      effort="0"
      velocity="10" />
  </joint>
  <link
    name="rignt_back">
    <inertial>
      <origin
        xyz="3.06629479585041E-08 -0.000632615479642107 -0.00543801795599769"
        rpy="0 0 0" />
      <mass
        value="2.92021652658196" />
      <inertia
        ixx="0.0159235360964885"
        ixy="-1.53104673061165E-08"
        ixz="-1.22794792883783E-08"
        iyy="0.0160692087758303"
        iyz="0.00125212851847895"
        izz="0.0266868659789182" />
    </inertial>
    <visual>
      <origin
        xyz="0 0 0"
        rpy="0 0 0" />
      <geometry>
        <mesh
          filename="package://agv/meshes/rignt_back.STL" />
      </geometry>
      <material
        name="">
        <color
          rgba="1 1 1 1" />
      </material>
    </visual>
    <collision>
      <origin
        xyz="0 0 0"
        rpy="0 0 0" />
      <geometry>
        <mesh
          filename="package://agv/meshes/rignt_back.STL" />
      </geometry>
    </collision>
  </link>
  <joint
    name="right_back_joint"
    type="continuous">
    <origin
      xyz="-0.30735 0.327 -0.527"
      rpy="0.11581 -1.5708 0" />
    <parent
      link="base_link" />
    <child
      link="rignt_back" />
    <axis
      xyz="0 0.11555 0.9933" />
    <limit
      lower="2"
      upper="10"
      effort="0"
      velocity="10" />
  </joint>
  <link
    name="left_front">
    <inertial>
      <origin
        xyz="3.0662E-08 0.00063262 0.005438"
        rpy="0 0 0" />
      <mass
        value="2.9202" />
      <inertia
        ixx="0.015924"
        ixy="1.5311E-08"
        ixz="1.228E-08"
        iyy="0.016069"
        iyz="0.0012521"
        izz="0.026687" />
    </inertial>
    <visual>
      <origin
        xyz="0 0 0"
        rpy="0 0 0" />
      <geometry>
        <mesh
          filename="package://agv/meshes/left_front.STL" />
      </geometry>
      <material
        name="">
        <color
          rgba="1 1 1 1" />
      </material>
    </visual>
    <collision>
      <origin
        xyz="0 0 0"
        rpy="0 0 0" />
      <geometry>
        <mesh
          filename="package://agv/meshes/left_front.STL" />
      </geometry>
    </collision>
  </link>
  <joint
    name="left_front_joint"
    type="continuous">
    <origin
      xyz="0.30735 -0.327 -0.527"
      rpy="-3.1378 -1.5708 0.11203" />
    <parent
      link="base_link" />
    <child
      link="left_front" />
    <axis
      xyz="0 0.11555 0.9933" />
    <limit
      lower="2"
      upper="10"
      effort="0"
      velocity="10" />
  </joint>
  <link
    name="right_front">
    <inertial>
      <origin
        xyz="-4.6099E-08 -4.2276E-08 -0.05776"
        rpy="0 0 0" />
      <mass
        value="2.9202" />
      <inertia
        ixx="0.015924"
        ixy="-1.6037E-08"
        ixz="-6.7331E-09"
        iyy="0.015924"
        iyz="4.7825E-09"
        izz="0.026833" />
    </inertial>
    <visual>
      <origin
        xyz="0 0 0"
        rpy="0 0 0" />
      <geometry>
        <mesh
          filename="package://agv/meshes/right_front.STL" />
      </geometry>
      <material
        name="">
        <color
          rgba="1 1 1 1" />
      </material>
    </visual>
    <collision>
      <origin
        xyz="0 0 0"
        rpy="0 0 0" />
      <geometry>
        <mesh
          filename="package://agv/meshes/right_front.STL" />
      </geometry>
    </collision>
  </link>
  <joint
    name="right_front_joint"
    type="continuous">
    <origin
      xyz="-0.25506 -0.327 -0.527"
      rpy="0 1.5708 0" />
    <parent
      link="base_link" />
    <child
      link="right_front" />
    <axis
      xyz="0 0 1" />
    <limit
      lower="2"
      upper="10"
      effort="0"
      velocity="10" />
  </joint>
</robot>